<?xml version="1.0" encoding="UTF-8"?>
<testsuite errors="1" failures="2" name="TestBookingService-20180701125001" skipped="0" tests="4" time="8.765" timestamp="2018-07-01T12:50:10">
	<testcase classname="TestBookingService" name="test_not_found" time="2.398" timestamp="2018-07-01T12:50:10"/>
	<testcase classname="TestBookingService" name="test_add_new_booking" time="3.584" timestamp="2018-07-01T12:50:05">
		<failure message="Items in the second set but not the first:
'267eedb8-0f5d-42d5-8f43-72426b9fb3e6'" type="AssertionError">
<![CDATA[Traceback (most recent call last):
  File "bookings.py", line 74, in test_add_new_booking
    self.assertEqual(set(actual_reply[payload['userid']][payload['showtimeid']]),set(GOOD_RESPONSES[payload['userid']][payload['showtimeid']]+[payload['movieid']]))
AssertionError: Items in the second set but not the first:
'267eedb8-0f5d-42d5-8f43-72426b9fb3e6'
]]>		</failure>
	</testcase>
	<testcase classname="TestBookingService" name="test_booking_records" time="2.498" timestamp="2018-07-01T12:50:08">
		<failure message="Got {u'status': 404, u'message': u'Not Found: http://127.0.0.1:5003/bookings/garret_heaton'} but expected {'20151201': ['267eedb8-0f5d-42d5-8f43-72426b9fb3e6'], '20151202': ['276c79ec-a26a-40a6-b3d3-fb242a5947b6']}" type="AssertionError">
<![CDATA[Traceback (most recent call last):
  File "bookings.py", line 54, in test_booking_records
    actual_reply, expected))
AssertionError: Got {u'status': 404, u'message': u'Not Found: http://127.0.0.1:5003/bookings/garret_heaton'} but expected {'20151201': ['267eedb8-0f5d-42d5-8f43-72426b9fb3e6'], '20151202': ['276c79ec-a26a-40a6-b3d3-fb242a5947b6']}
]]>		</failure>
	</testcase>
	<testcase classname="TestBookingService" name="test_delete_booking" time="0.285" timestamp="2018-07-01T12:50:08">
		<error message="No JSON object could be decoded" type="ValueError">
<![CDATA[Traceback (most recent call last):
  File "bookings.py", line 85, in test_delete_booking
    actual_reply = actual_reply.json()
  File "C:\Users\abc\AppData\Local\Enthought\Canopy\edm\envs\User\lib\site-packages\requests\models.py", line 799, in json
    return json.loads(self.text, **kwargs)
  File "C:\Users\abc\AppData\Local\Enthought\Canopy\edm\envs\User\lib\json\__init__.py", line 339, in loads
    return _default_decoder.decode(s)
  File "C:\Users\abc\AppData\Local\Enthought\Canopy\edm\envs\User\lib\json\decoder.py", line 364, in decode
    obj, end = self.raw_decode(s, idx=_w(s, 0).end())
  File "C:\Users\abc\AppData\Local\Enthought\Canopy\edm\envs\User\lib\json\decoder.py", line 382, in raw_decode
    raise ValueError("No JSON object could be decoded")
ValueError: No JSON object could be decoded
]]>		</error>
	</testcase>
	<system-out>
<![CDATA[garret_heaton {'20151201': ['267eedb8-0f5d-42d5-8f43-72426b9fb3e6'], '20151202': ['276c79ec-a26a-40a6-b3d3-fb242a5947b6']}
]]>	</system-out>
	<system-err>
<![CDATA[]]>	</system-err>
</testsuite>
